<?xml version="1.0"?>

<robot xmlns:xacro="http://ros.org/wiki/xacro">
  <xacro:property name="M_PI" value="3.1415926535897931" />

  <xacro:macro name="hokuyo_utm30lx" params="name parent *origin ros_topic update_rate ray_count min_angle max_angle">
    <link name="${name}_frame">
      <inertial>
        <mass value="0.010" />
        <origin xyz="0 0 0" rpy="0 0 0" />
        <inertia ixx="2.632e-6" ixy="0" ixz="0" iyy="2.632e-6" iyz="0" izz="1.62e-6" />
      </inertial>
      <visual>
        <origin xyz="0 0 0" rpy="0 0 0" />
        <geometry>
          <mesh filename="package://mrsl_models/models/sensors/hokuyo_utm_30lx/utm_30lx.dae"/>
        </geometry>
      </visual>
   </link>

    <joint name="${name}_joint" type="continuous">
      <xacro:insert_block name="origin" />
      <parent link="${parent}"/>
      <child link="${name}_frame"/>
      <axis xyz="0 1 0" rpy="0 0 0" />
      <limit effort="100" velocity="10"/>
      <joint_properties damping="0.0" friction="0.0"/>
    </joint>

    <gazebo reference="${name}_frame">
      <sensor type="ray" name="${name}">
        <always_on>true</always_on>
        <update_rate>${update_rate}</update_rate>
        <pose>0 0 0 0 0 0</pose>
        <visualize>false</visualize>
        <ray>
          <scan>
            <horizontal>
              <samples>${ray_count}</samples>
              <resolution>1</resolution>
              <min_angle>${min_angle * M_PI/180}</min_angle>
              <max_angle>${max_angle * M_PI/180}</max_angle>
            </horizontal>
          </scan>
          <range>
            <min>0.1</min>
            <max>30.0</max>
            <resolution>0.01</resolution>
          </range>
        </ray>
        <plugin name="gazebo_ros_${name}_controller" filename="libgazebo_ros_laser.so">
          <gaussianNoise>0.005</gaussianNoise>
          <alwaysOn>true</alwaysOn>
          <updateRate>${update_rate}</updateRate>
          <topicName>${ros_topic}</topicName>
          <frameName>${name}_frame</frameName>
        </plugin>
      </sensor>
    </gazebo>
  </xacro:macro>
</robot>

